<robot name = "robot">
    <link name="Cube0">
        <inertial>
            <origin xyz="0 0 0.5" rpy="0 0 0"/>
            <mass value="1" />
            <inertia ixx="100" ixy="0" ixz="0" iyy="100" iyz="0" izz="100" />
        </inertial>
        <visual>
            <origin xyz="0 0 0.5" rpy="0 0 0"/>
            <geometry>
                <box size="0.26837121767644656 0.3294055604764292 0.21791903675394964" />
            </geometry>
            <material name="Cyan">
                <color rgba="0 1.0 1.0 1.0"/>
            </material>
        </visual>
        <collision>
            <origin xyz="0 0 0.5" rpy="0 0 0"/>
            <geometry>
                <box size="0.26837121767644656 0.3294055604764292 0.21791903675394964" />
            </geometry>
        </collision>
    </link>
    <joint name="Cube0_Cube1" type="revolute">
       <parent link="Cube0"/>
       <child  link="Cube1"/>
       <origin rpy="0 0 0" xyz="0.13418560883822328 0 0.5" />
     <axis xyz="0 0 1"/>
       <limit effort="0.0" lower="-3.14159" upper="3.14159" velocity="0.0"/>
    </joint>
    <link name="Cube1">
        <inertial>
            <origin xyz="0.16976821996362773 0 0" rpy="0 0 0"/>
            <mass value="1" />
            <inertia ixx="100" ixy="0" ixz="0" iyy="100" iyz="0" izz="100" />
        </inertial>
        <visual>
            <origin xyz="0.16976821996362773 0 0" rpy="0 0 0"/>
            <geometry>
                <box size="0.33953643992725546 0.19154473814974765 0.14985584372786614" />
            </geometry>
            <material name="Cyan">
                <color rgba="0 1.0 1.0 1.0"/>
            </material>
        </visual>
        <collision>
            <origin xyz="0.16976821996362773 0 0" rpy="0 0 0"/>
            <geometry>
                <box size="0.33953643992725546 0.19154473814974765 0.14985584372786614" />
            </geometry>
        </collision>
    </link>
    <joint name="Cube1_Cube2" type="revolute">
       <parent link="Cube1"/>
       <child  link="Cube2"/>
       <origin rpy="0 0 0" xyz="0.33953643992725546 0 0" />
     <axis xyz="0 0 1"/>
       <limit effort="0.0" lower="-3.14159" upper="3.14159" velocity="0.0"/>
    </joint>
    <link name="Cube2">
        <inertial>
            <origin xyz="0.12894897725830615 0 0" rpy="0 0 0"/>
            <mass value="1" />
            <inertia ixx="100" ixy="0" ixz="0" iyy="100" iyz="0" izz="100" />
        </inertial>
        <visual>
            <origin xyz="0.12894897725830615 0 0" rpy="0 0 0"/>
            <geometry>
                <box size="0.2578979545166123 0.28120607499198114 0.34578198841434526" />
            </geometry>
            <material name="Cyan">
                <color rgba="0 1.0 1.0 1.0"/>
            </material>
        </visual>
        <collision>
            <origin xyz="0.12894897725830615 0 0" rpy="0 0 0"/>
            <geometry>
                <box size="0.2578979545166123 0.28120607499198114 0.34578198841434526" />
            </geometry>
        </collision>
    </link>
    <joint name="Cube2_Cube3" type="revolute">
       <parent link="Cube2"/>
       <child  link="Cube3"/>
       <origin rpy="0 0 0" xyz="0.2578979545166123 0 0" />
     <axis xyz="0 0 1"/>
       <limit effort="0.0" lower="-3.14159" upper="3.14159" velocity="0.0"/>
    </joint>
    <link name="Cube3">
        <inertial>
            <origin xyz="0.08497703538295184 0 0" rpy="0 0 0"/>
            <mass value="1" />
            <inertia ixx="100" ixy="0" ixz="0" iyy="100" iyz="0" izz="100" />
        </inertial>
        <visual>
            <origin xyz="0.08497703538295184 0 0" rpy="0 0 0"/>
            <geometry>
                <box size="0.1699540707659037 0.14933516278266917 0.15948665405488835" />
            </geometry>
            <material name="Green">
                <color rgba="0.0 1.0 0.0 1.0"/>
            </material>
        </visual>
        <collision>
            <origin xyz="0.08497703538295184 0 0" rpy="0 0 0"/>
            <geometry>
                <box size="0.1699540707659037 0.14933516278266917 0.15948665405488835" />
            </geometry>
        </collision>
    </link>
</robot>