<robot name = "robot">
    <link name="Cube0">
        <inertial>
            <origin xyz="0 0 0.5" rpy="0 0 0"/>
            <mass value="1" />
            <inertia ixx="100" ixy="0" ixz="0" iyy="100" iyz="0" izz="100" />
        </inertial>
        <visual>
            <origin xyz="0 0 0.5" rpy="0 0 0"/>
            <geometry>
                <box size="0.2 0.2 0.2" />
            </geometry>
            <material name="Green">
                <color rgba="0.0 1.0 0.0 1.0"/>
            </material>
        </visual>
        <collision>
            <origin xyz="0 0 0.5" rpy="0 0 0"/>
            <geometry>
                <box size="0.2 0.2 0.2" />
            </geometry>
        </collision>
    </link>
    <joint name="Cube0_Cube1" type="revolute">
       <parent link="Cube0"/>
       <child  link="Cube1"/>
       <origin rpy="0 0 0" xyz="0.1 0 0.5" />
     <axis xyz="0 0 1"/>
       <limit effort="0.0" lower="-3.14159" upper="3.14159" velocity="0.0"/>
    </joint>
    <joint name="Cube0_Cube2" type="revolute">
       <parent link="Cube0"/>
       <child  link="Cube2"/>
       <origin rpy="0 0 0" xyz="-0.1 0 0.5" />
     <axis xyz="0 0 1"/>
       <limit effort="0.0" lower="-3.14159" upper="3.14159" velocity="0.0"/>
    </joint>
    <link name="Cube1">
        <inertial>
            <origin xyz="0.1 0 0" rpy="0 0 0"/>
            <mass value="1" />
            <inertia ixx="100" ixy="0" ixz="0" iyy="100" iyz="0" izz="100" />
        </inertial>
        <visual>
            <origin xyz="0.1 0 0" rpy="0 0 0"/>
            <geometry>
                <box size="0.1434937171844097 0.2 0.12621903591042552" />
            </geometry>
            <material name="Green">
                <color rgba="0.0 1.0 0.0 1.0"/>
            </material>
        </visual>
        <collision>
            <origin xyz="0.1 0 0" rpy="0 0 0"/>
            <geometry>
                <box size="0.1434937171844097 0.2 0.12621903591042552" />
            </geometry>
        </collision>
    </link>
    <link name="Cube2">
        <inertial>
            <origin xyz="-0.1 0 0" rpy="0 0 0"/>
            <mass value="1" />
            <inertia ixx="100" ixy="0" ixz="0" iyy="100" iyz="0" izz="100" />
        </inertial>
        <visual>
            <origin xyz="-0.1 0 0" rpy="0 0 0"/>
            <geometry>
                <box size="0.14977656894585403 0.16836855617027807 0.15368151665097168" />
            </geometry>
            <material name="Cyan">
                <color rgba="0 1.0 1.0 1.0"/>
            </material>
        </visual>
        <collision>
            <origin xyz="-0.1 0 0" rpy="0 0 0"/>
            <geometry>
                <box size="0.14977656894585403 0.16836855617027807 0.15368151665097168" />
            </geometry>
        </collision>
    </link>
    <joint name="Cube1_Cube3" type="revolute">
       <parent link="Cube1"/>
       <child  link="Cube3"/>
       <origin rpy="0 0 0" xyz="0 0.1 0" />
     <axis xyz="0 0 1"/>
       <limit effort="0.0" lower="-3.14159" upper="3.14159" velocity="0.0"/>
    </joint>
    <link name="Cube3">
        <inertial>
            <origin xyz="0 0.1 0" rpy="0 0 0"/>
            <mass value="1" />
            <inertia ixx="100" ixy="0" ixz="0" iyy="100" iyz="0" izz="100" />
        </inertial>
        <visual>
            <origin xyz="0 0.1 0" rpy="0 0 0"/>
            <geometry>
                <box size="0.2 0.3772245547899873 0.23990837595378098" />
            </geometry>
            <material name="Cyan">
                <color rgba="0 1.0 1.0 1.0"/>
            </material>
        </visual>
        <collision>
            <origin xyz="0 0.1 0" rpy="0 0 0"/>
            <geometry>
                <box size="0.2 0.3772245547899873 0.23990837595378098" />
            </geometry>
        </collision>
    </link>
</robot>