<robot name = "robot">
    <link name="Cube0">
        <inertial>
            <origin xyz="0 0 0.5" rpy="0 0 0"/>
            <mass value="1" />
            <inertia ixx="100" ixy="0" ixz="0" iyy="100" iyz="0" izz="100" />
        </inertial>
        <visual>
            <origin xyz="0 0 0.5" rpy="0 0 0"/>
            <geometry>
                <box size="0.2 0.2 0.2" />
            </geometry>
            <material name="Green">
                <color rgba="0.0 1.0 0.0 1.0"/>
            </material>
        </visual>
        <collision>
            <origin xyz="0 0 0.5" rpy="0 0 0"/>
            <geometry>
                <box size="0.2 0.2 0.2" />
            </geometry>
        </collision>
    </link>
    <joint name="Cube0_Cube1" type="revolute">
       <parent link="Cube0"/>
       <child  link="Cube1"/>
       <origin rpy="0 0 0" xyz="0.1 0 0.5" />
     <axis xyz="0 0 1"/>
       <limit effort="0.0" lower="-3.14159" upper="3.14159" velocity="0.0"/>
    </joint>
    <joint name="Cube0_Cube2" type="revolute">
       <parent link="Cube0"/>
       <child  link="Cube2"/>
       <origin rpy="0 0 0" xyz="-0.1 0 0.5" />
     <axis xyz="0 0 1"/>
       <limit effort="0.0" lower="-3.14159" upper="3.14159" velocity="0.0"/>
    </joint>
    <link name="Cube1">
        <inertial>
            <origin xyz="0.1 0 0" rpy="0 0 0"/>
            <mass value="1" />
            <inertia ixx="100" ixy="0" ixz="0" iyy="100" iyz="0" izz="100" />
        </inertial>
        <visual>
            <origin xyz="0.1 0 0" rpy="0 0 0"/>
            <geometry>
                <box size="0.3913909664123233 0.2 0.22300508805072716" />
            </geometry>
            <material name="Green">
                <color rgba="0.0 1.0 0.0 1.0"/>
            </material>
        </visual>
        <collision>
            <origin xyz="0.1 0 0" rpy="0 0 0"/>
            <geometry>
                <box size="0.3913909664123233 0.2 0.22300508805072716" />
            </geometry>
        </collision>
    </link>
    <link name="Cube2">
        <inertial>
            <origin xyz="-0.1 0 0" rpy="0 0 0"/>
            <mass value="1" />
            <inertia ixx="100" ixy="0" ixz="0" iyy="100" iyz="0" izz="100" />
        </inertial>
        <visual>
            <origin xyz="-0.1 0 0" rpy="0 0 0"/>
            <geometry>
                <box size="0.1607205173825933 0.30618817736141934 0.3026644169862168" />
            </geometry>
            <material name="Cyan">
                <color rgba="0 1.0 1.0 1.0"/>
            </material>
        </visual>
        <collision>
            <origin xyz="-0.1 0 0" rpy="0 0 0"/>
            <geometry>
                <box size="0.1607205173825933 0.30618817736141934 0.3026644169862168" />
            </geometry>
        </collision>
    </link>
    <joint name="Cube1_Cube3" type="revolute">
       <parent link="Cube1"/>
       <child  link="Cube3"/>
       <origin rpy="0 0 0" xyz="0 0.1 0" />
     <axis xyz="0 0 1"/>
       <limit effort="0.0" lower="-3.14159" upper="3.14159" velocity="0.0"/>
    </joint>
    <link name="Cube3">
        <inertial>
            <origin xyz="0 0.1 0" rpy="0 0 0"/>
            <mass value="1" />
            <inertia ixx="100" ixy="0" ixz="0" iyy="100" iyz="0" izz="100" />
        </inertial>
        <visual>
            <origin xyz="0 0.1 0" rpy="0 0 0"/>
            <geometry>
                <box size="0.2 0.11495657785366319 0.15748847869589472" />
            </geometry>
            <material name="Cyan">
                <color rgba="0 1.0 1.0 1.0"/>
            </material>
        </visual>
        <collision>
            <origin xyz="0 0.1 0" rpy="0 0 0"/>
            <geometry>
                <box size="0.2 0.11495657785366319 0.15748847869589472" />
            </geometry>
        </collision>
    </link>
</robot>